2020-03-23 19:53:48,494 ERROR: Exception on /Inventory [GET] [in c:\users\sgoli\documents\flask-app\venv\lib\site-packages\flask\app.py:1891]
Traceback (most recent call last):
  File "c:\users\sgoli\documents\flask-app\venv\lib\site-packages\flask\app.py", line 2446, in wsgi_app
    response = self.full_dispatch_request()
  File "c:\users\sgoli\documents\flask-app\venv\lib\site-packages\flask\app.py", line 1951, in full_dispatch_request
    rv = self.handle_user_exception(e)
  File "c:\users\sgoli\documents\flask-app\venv\lib\site-packages\flask\app.py", line 1820, in handle_user_exception
    reraise(exc_type, exc_value, tb)
  File "c:\users\sgoli\documents\flask-app\venv\lib\site-packages\flask\_compat.py", line 39, in reraise
    raise value
  File "c:\users\sgoli\documents\flask-app\venv\lib\site-packages\flask\app.py", line 1949, in full_dispatch_request
    rv = self.dispatch_request()
  File "c:\users\sgoli\documents\flask-app\venv\lib\site-packages\flask\app.py", line 1935, in dispatch_request
    return self.view_functions[rule.endpoint](**req.view_args)
  File "c:\users\sgoli\documents\flask-app\venv\lib\site-packages\flask_login\utils.py", line 272, in decorated_view
    return func(*args, **kwargs)
  File "C:\Users\sgoli\Documents\flask-app\app\routes.py", line 47, in inventory
    jsonOutput = jsonify(output=output)
  File "c:\users\sgoli\documents\flask-app\venv\lib\site-packages\flask\json\__init__.py", line 370, in jsonify
    dumps(data, indent=indent, separators=separators) + "\n",
  File "c:\users\sgoli\documents\flask-app\venv\lib\site-packages\flask\json\__init__.py", line 211, in dumps
    rv = _json.dumps(obj, **kwargs)
  File "C:\Users\sgoli\AppData\Local\Programs\Python\Python37-32\lib\json\__init__.py", line 238, in dumps
    **kw).encode(obj)
  File "C:\Users\sgoli\AppData\Local\Programs\Python\Python37-32\lib\json\encoder.py", line 199, in encode
    chunks = self.iterencode(o, _one_shot=True)
  File "C:\Users\sgoli\AppData\Local\Programs\Python\Python37-32\lib\json\encoder.py", line 257, in iterencode
    return _iterencode(o, 0)
  File "c:\users\sgoli\documents\flask-app\venv\lib\site-packages\flask\json\__init__.py", line 100, in default
    return _json.JSONEncoder.default(self, o)
  File "C:\Users\sgoli\AppData\Local\Programs\Python\Python37-32\lib\json\encoder.py", line 179, in default
    raise TypeError(f'Object of type {o.__class__.__name__} '
TypeError: Object of type InstanceState is not JSON serializable
2020-03-23 19:54:46,821 INFO: Microblog startup [in C:\Users\sgoli\Documents\flask-app\app\__init__.py:51]
2020-03-23 19:57:15,432 INFO: Microblog startup [in C:\Users\sgoli\Documents\flask-app\app\__init__.py:51]
2020-03-23 19:57:23,495 ERROR: Exception on /Inventory [GET] [in c:\users\sgoli\documents\flask-app\venv\lib\site-packages\flask\app.py:1891]
Traceback (most recent call last):
  File "c:\users\sgoli\documents\flask-app\venv\lib\site-packages\flask\app.py", line 2446, in wsgi_app
    response = self.full_dispatch_request()
  File "c:\users\sgoli\documents\flask-app\venv\lib\site-packages\flask\app.py", line 1951, in full_dispatch_request
    rv = self.handle_user_exception(e)
  File "c:\users\sgoli\documents\flask-app\venv\lib\site-packages\flask\app.py", line 1820, in handle_user_exception
    reraise(exc_type, exc_value, tb)
  File "c:\users\sgoli\documents\flask-app\venv\lib\site-packages\flask\_compat.py", line 39, in reraise
    raise value
  File "c:\users\sgoli\documents\flask-app\venv\lib\site-packages\flask\app.py", line 1949, in full_dispatch_request
    rv = self.dispatch_request()
  File "c:\users\sgoli\documents\flask-app\venv\lib\site-packages\flask\app.py", line 1935, in dispatch_request
    return self.view_functions[rule.endpoint](**req.view_args)
  File "c:\users\sgoli\documents\flask-app\venv\lib\site-packages\flask_login\utils.py", line 272, in decorated_view
    return func(*args, **kwargs)
  File "C:\Users\sgoli\Documents\flask-app\app\routes.py", line 50, in inventory
    print(inventory_schema.dump(inventory).data)
AttributeError: 'list' object has no attribute 'data'
2020-03-23 20:04:36,179 INFO: Microblog startup [in C:\Users\sgoli\Documents\flask-app\app\__init__.py:51]
2020-03-23 20:05:44,360 INFO: Microblog startup [in C:\Users\sgoli\Documents\flask-app\app\__init__.py:51]
2020-03-23 20:15:34,597 INFO: Microblog startup [in C:\Users\sgoli\Documents\flask-app\app\__init__.py:51]
2020-03-23 20:16:40,305 INFO: Microblog startup [in C:\Users\sgoli\Documents\flask-app\app\__init__.py:51]
2020-03-23 20:17:07,494 INFO: Microblog startup [in C:\Users\sgoli\Documents\flask-app\app\__init__.py:51]
2020-03-23 20:18:47,247 INFO: Microblog startup [in C:\Users\sgoli\Documents\flask-app\app\__init__.py:51]
2020-03-23 20:44:02,743 INFO: Microblog startup [in C:\Users\sgoli\Documents\flask-app\app\__init__.py:51]
2020-03-23 20:44:18,422 INFO: Microblog startup [in C:\Users\sgoli\Documents\flask-app\app\__init__.py:51]
2020-03-23 20:44:22,441 ERROR: Exception on /Inventory [GET] [in c:\users\sgoli\documents\flask-app\venv\lib\site-packages\flask\app.py:1891]
Traceback (most recent call last):
  File "c:\users\sgoli\documents\flask-app\venv\lib\site-packages\flask\app.py", line 2446, in wsgi_app
    response = self.full_dispatch_request()
  File "c:\users\sgoli\documents\flask-app\venv\lib\site-packages\flask\app.py", line 1951, in full_dispatch_request
    rv = self.handle_user_exception(e)
  File "c:\users\sgoli\documents\flask-app\venv\lib\site-packages\flask\app.py", line 1820, in handle_user_exception
    reraise(exc_type, exc_value, tb)
  File "c:\users\sgoli\documents\flask-app\venv\lib\site-packages\flask\_compat.py", line 39, in reraise
    raise value
  File "c:\users\sgoli\documents\flask-app\venv\lib\site-packages\flask\app.py", line 1949, in full_dispatch_request
    rv = self.dispatch_request()
  File "c:\users\sgoli\documents\flask-app\venv\lib\site-packages\flask\app.py", line 1935, in dispatch_request
    return self.view_functions[rule.endpoint](**req.view_args)
  File "c:\users\sgoli\documents\flask-app\venv\lib\site-packages\flask_login\utils.py", line 272, in decorated_view
    return func(*args, **kwargs)
  File "C:\Users\sgoli\Documents\flask-app\app\routes.py", line 51, in inventory
    inventoryJSON = jsonify(inventory_schema.dump(inventory)).dumps
AttributeError: 'Response' object has no attribute 'dumps'
2020-03-23 20:45:32,641 INFO: Microblog startup [in C:\Users\sgoli\Documents\flask-app\app\__init__.py:51]
2020-03-23 20:47:12,422 INFO: Microblog startup [in C:\Users\sgoli\Documents\flask-app\app\__init__.py:51]
2020-03-23 20:47:20,208 ERROR: Exception on /Inventory [GET] [in c:\users\sgoli\documents\flask-app\venv\lib\site-packages\flask\app.py:1891]
Traceback (most recent call last):
  File "c:\users\sgoli\documents\flask-app\venv\lib\site-packages\flask\app.py", line 2446, in wsgi_app
    response = self.full_dispatch_request()
  File "c:\users\sgoli\documents\flask-app\venv\lib\site-packages\flask\app.py", line 1951, in full_dispatch_request
    rv = self.handle_user_exception(e)
  File "c:\users\sgoli\documents\flask-app\venv\lib\site-packages\flask\app.py", line 1820, in handle_user_exception
    reraise(exc_type, exc_value, tb)
  File "c:\users\sgoli\documents\flask-app\venv\lib\site-packages\flask\_compat.py", line 39, in reraise
    raise value
  File "c:\users\sgoli\documents\flask-app\venv\lib\site-packages\flask\app.py", line 1949, in full_dispatch_request
    rv = self.dispatch_request()
  File "c:\users\sgoli\documents\flask-app\venv\lib\site-packages\flask\app.py", line 1935, in dispatch_request
    return self.view_functions[rule.endpoint](**req.view_args)
  File "c:\users\sgoli\documents\flask-app\venv\lib\site-packages\flask_login\utils.py", line 272, in decorated_view
    return func(*args, **kwargs)
  File "C:\Users\sgoli\Documents\flask-app\app\routes.py", line 51, in inventory
    inventoryJSON = json.jsonify(inventory_schema.dump(inventory))
AttributeError: module 'json' has no attribute 'jsonify'
2020-03-23 20:48:18,613 INFO: Microblog startup [in C:\Users\sgoli\Documents\flask-app\app\__init__.py:51]
2020-03-23 21:01:05,901 INFO: Microblog startup [in C:\Users\sgoli\Documents\flask-app\app\__init__.py:51]
2020-03-23 21:03:07,731 INFO: Microblog startup [in C:\Users\sgoli\Documents\flask-app\app\__init__.py:51]
2020-03-23 21:04:53,931 INFO: Microblog startup [in C:\Users\sgoli\Documents\flask-app\app\__init__.py:51]
