2020-03-24 13:36:51,218 INFO: Microblog startup [in C:\Users\sgoli\Documents\flask-app\app\__init__.py:51]
2020-03-24 13:39:22,319 INFO: Microblog startup [in C:\Users\sgoli\Documents\flask-app\app\__init__.py:51]
2020-03-24 13:40:55,021 INFO: Microblog startup [in C:\Users\sgoli\Documents\flask-app\app\__init__.py:51]
2020-03-24 13:45:27,127 INFO: Microblog startup [in C:\Users\sgoli\Documents\flask-app\app\__init__.py:51]
2020-03-24 13:50:12,501 INFO: Microblog startup [in C:\Users\sgoli\Documents\flask-app\app\__init__.py:51]
2020-03-24 13:56:59,429 INFO: Microblog startup [in C:\Users\sgoli\Documents\flask-app\app\__init__.py:51]
2020-03-24 13:58:59,941 INFO: Microblog startup [in C:\Users\sgoli\Documents\flask-app\app\__init__.py:51]
2020-03-24 14:04:22,670 INFO: Microblog startup [in C:\Users\sgoli\Documents\flask-app\app\__init__.py:51]
2020-03-24 14:05:00,472 INFO: Microblog startup [in C:\Users\sgoli\Documents\flask-app\app\__init__.py:51]
2020-03-24 14:05:19,208 INFO: Microblog startup [in C:\Users\sgoli\Documents\flask-app\app\__init__.py:51]
2020-03-24 14:06:01,076 INFO: Microblog startup [in C:\Users\sgoli\Documents\flask-app\app\__init__.py:51]
2020-03-24 17:14:57,868 INFO: Microblog startup [in C:\Users\sgoli\Documents\flask-app\app\__init__.py:51]
2020-03-24 17:15:46,426 INFO: Microblog startup [in C:\Users\sgoli\Documents\flask-app\app\__init__.py:51]
2020-03-24 17:15:56,302 ERROR: Exception on /Inventory [GET] [in c:\users\sgoli\documents\flask-app\venv\lib\site-packages\flask\app.py:1891]
Traceback (most recent call last):
  File "c:\users\sgoli\documents\flask-app\venv\lib\site-packages\flask\app.py", line 2446, in wsgi_app
    response = self.full_dispatch_request()
  File "c:\users\sgoli\documents\flask-app\venv\lib\site-packages\flask\app.py", line 1951, in full_dispatch_request
    rv = self.handle_user_exception(e)
  File "c:\users\sgoli\documents\flask-app\venv\lib\site-packages\flask\app.py", line 1820, in handle_user_exception
    reraise(exc_type, exc_value, tb)
  File "c:\users\sgoli\documents\flask-app\venv\lib\site-packages\flask\_compat.py", line 39, in reraise
    raise value
  File "c:\users\sgoli\documents\flask-app\venv\lib\site-packages\flask\app.py", line 1949, in full_dispatch_request
    rv = self.dispatch_request()
  File "c:\users\sgoli\documents\flask-app\venv\lib\site-packages\flask\app.py", line 1935, in dispatch_request
    return self.view_functions[rule.endpoint](**req.view_args)
  File "c:\users\sgoli\documents\flask-app\venv\lib\site-packages\flask_login\utils.py", line 272, in decorated_view
    return func(*args, **kwargs)
  File "C:\Users\sgoli\Documents\flask-app\app\routes.py", line 54, in inventory
    pageInventory = inventory.paginate(page, app.config['POSTS_PER_PAGE'], False)
AttributeError: 'list' object has no attribute 'paginate'
2020-03-24 17:17:07,627 INFO: Microblog startup [in C:\Users\sgoli\Documents\flask-app\app\__init__.py:51]
2020-03-24 17:17:40,778 INFO: Microblog startup [in C:\Users\sgoli\Documents\flask-app\app\__init__.py:51]
2020-03-24 17:20:49,820 INFO: Microblog startup [in C:\Users\sgoli\Documents\flask-app\app\__init__.py:51]
2020-03-24 17:21:01,718 ERROR: Exception on /Inventory [GET] [in c:\users\sgoli\documents\flask-app\venv\lib\site-packages\flask\app.py:1891]
Traceback (most recent call last):
  File "c:\users\sgoli\documents\flask-app\venv\lib\site-packages\flask\app.py", line 2446, in wsgi_app
    response = self.full_dispatch_request()
  File "c:\users\sgoli\documents\flask-app\venv\lib\site-packages\flask\app.py", line 1951, in full_dispatch_request
    rv = self.handle_user_exception(e)
  File "c:\users\sgoli\documents\flask-app\venv\lib\site-packages\flask\app.py", line 1820, in handle_user_exception
    reraise(exc_type, exc_value, tb)
  File "c:\users\sgoli\documents\flask-app\venv\lib\site-packages\flask\_compat.py", line 39, in reraise
    raise value
  File "c:\users\sgoli\documents\flask-app\venv\lib\site-packages\flask\app.py", line 1949, in full_dispatch_request
    rv = self.dispatch_request()
  File "c:\users\sgoli\documents\flask-app\venv\lib\site-packages\flask\app.py", line 1935, in dispatch_request
    return self.view_functions[rule.endpoint](**req.view_args)
  File "c:\users\sgoli\documents\flask-app\venv\lib\site-packages\flask_login\utils.py", line 272, in decorated_view
    return func(*args, **kwargs)
  File "C:\Users\sgoli\Documents\flask-app\app\routes.py", line 57, in inventory
    inventoryJSON2 = json.dumps(inventory_schema.dump(pageInventory))
  File "c:\users\sgoli\documents\flask-app\venv\lib\site-packages\marshmallow\schema.py", line 556, in dump
    result = self._serialize(processed_obj, many=many)
  File "c:\users\sgoli\documents\flask-app\venv\lib\site-packages\marshmallow\schema.py", line 516, in _serialize
    for d in typing.cast(typing.Iterable[_T], obj)
TypeError: 'Pagination' object is not iterable
2020-03-24 17:22:08,610 INFO: Microblog startup [in C:\Users\sgoli\Documents\flask-app\app\__init__.py:51]
2020-03-25 09:53:44,600 INFO: Microblog startup [in C:\Users\sgoli\Documents\flask-app\app\__init__.py:51]
2020-03-25 09:54:17,242 INFO: Microblog startup [in C:\Users\sgoli\Documents\flask-app\app\__init__.py:51]
2020-03-25 12:41:40,198 INFO: Microblog startup [in C:\Users\sgoli\Documents\flask-app\app\__init__.py:51]
2020-03-25 12:41:56,165 ERROR: Exception on /TestPage [GET] [in c:\users\sgoli\documents\flask-app\venv\lib\site-packages\flask\app.py:1891]
Traceback (most recent call last):
  File "c:\users\sgoli\documents\flask-app\venv\lib\site-packages\flask\app.py", line 2446, in wsgi_app
    response = self.full_dispatch_request()
  File "c:\users\sgoli\documents\flask-app\venv\lib\site-packages\flask\app.py", line 1951, in full_dispatch_request
    rv = self.handle_user_exception(e)
  File "c:\users\sgoli\documents\flask-app\venv\lib\site-packages\flask\app.py", line 1820, in handle_user_exception
    reraise(exc_type, exc_value, tb)
  File "c:\users\sgoli\documents\flask-app\venv\lib\site-packages\flask\_compat.py", line 39, in reraise
    raise value
  File "c:\users\sgoli\documents\flask-app\venv\lib\site-packages\flask\app.py", line 1949, in full_dispatch_request
    rv = self.dispatch_request()
  File "c:\users\sgoli\documents\flask-app\venv\lib\site-packages\flask\app.py", line 1935, in dispatch_request
    return self.view_functions[rule.endpoint](**req.view_args)
  File "c:\users\sgoli\documents\flask-app\venv\lib\site-packages\flask_login\utils.py", line 272, in decorated_view
    return func(*args, **kwargs)
TypeError: testpage() missing 1 required positional argument: 'request'
2020-03-25 12:46:01,254 INFO: Microblog startup [in C:\Users\sgoli\Documents\flask-app\app\__init__.py:51]
2020-03-25 12:46:08,604 ERROR: Exception on /TestPage [GET] [in c:\users\sgoli\documents\flask-app\venv\lib\site-packages\flask\app.py:1891]
Traceback (most recent call last):
  File "c:\users\sgoli\documents\flask-app\venv\lib\site-packages\flask\app.py", line 2446, in wsgi_app
    response = self.full_dispatch_request()
  File "c:\users\sgoli\documents\flask-app\venv\lib\site-packages\flask\app.py", line 1951, in full_dispatch_request
    rv = self.handle_user_exception(e)
  File "c:\users\sgoli\documents\flask-app\venv\lib\site-packages\flask\app.py", line 1820, in handle_user_exception
    reraise(exc_type, exc_value, tb)
  File "c:\users\sgoli\documents\flask-app\venv\lib\site-packages\flask\_compat.py", line 39, in reraise
    raise value
  File "c:\users\sgoli\documents\flask-app\venv\lib\site-packages\flask\app.py", line 1949, in full_dispatch_request
    rv = self.dispatch_request()
  File "c:\users\sgoli\documents\flask-app\venv\lib\site-packages\flask\app.py", line 1935, in dispatch_request
    return self.view_functions[rule.endpoint](**req.view_args)
  File "c:\users\sgoli\documents\flask-app\venv\lib\site-packages\flask_login\utils.py", line 272, in decorated_view
    return func(*args, **kwargs)
  File "C:\Users\sgoli\Documents\flask-app\app\routes.py", line 74, in testpage
    inventoryJSON = json.dumps(inventory_schema.dump(pageInventory.items))
NameError: name 'inventory_schema' is not defined
2020-03-25 12:46:10,980 ERROR: Exception on /TestPage [GET] [in c:\users\sgoli\documents\flask-app\venv\lib\site-packages\flask\app.py:1891]
Traceback (most recent call last):
  File "c:\users\sgoli\documents\flask-app\venv\lib\site-packages\flask\app.py", line 2446, in wsgi_app
    response = self.full_dispatch_request()
  File "c:\users\sgoli\documents\flask-app\venv\lib\site-packages\flask\app.py", line 1951, in full_dispatch_request
    rv = self.handle_user_exception(e)
  File "c:\users\sgoli\documents\flask-app\venv\lib\site-packages\flask\app.py", line 1820, in handle_user_exception
    reraise(exc_type, exc_value, tb)
  File "c:\users\sgoli\documents\flask-app\venv\lib\site-packages\flask\_compat.py", line 39, in reraise
    raise value
  File "c:\users\sgoli\documents\flask-app\venv\lib\site-packages\flask\app.py", line 1949, in full_dispatch_request
    rv = self.dispatch_request()
  File "c:\users\sgoli\documents\flask-app\venv\lib\site-packages\flask\app.py", line 1935, in dispatch_request
    return self.view_functions[rule.endpoint](**req.view_args)
  File "c:\users\sgoli\documents\flask-app\venv\lib\site-packages\flask_login\utils.py", line 272, in decorated_view
    return func(*args, **kwargs)
  File "C:\Users\sgoli\Documents\flask-app\app\routes.py", line 74, in testpage
    inventoryJSON = json.dumps(inventory_schema.dump(pageInventory.items))
NameError: name 'inventory_schema' is not defined
2020-03-25 12:46:36,134 INFO: Microblog startup [in C:\Users\sgoli\Documents\flask-app\app\__init__.py:51]
2020-03-25 13:39:51,518 INFO: Microblog startup [in C:\Users\sgoli\Documents\flask-app\app\__init__.py:51]
2020-03-26 13:52:31,406 INFO: Microblog startup [in C:\Users\sgoli\Documents\flask-app\app\__init__.py:51]
2020-03-26 13:57:58,358 INFO: Microblog startup [in C:\Users\sgoli\Documents\flask-app\app\__init__.py:51]
